Workbook
Name coeff_c_2CCEE246_9945_2140_BC14_9589485B31D0_0fd1f8c5_b793_4c6a_9738_c66d803607aa: '⚡ Leads'!$E$1
Name coeff_c_2CCEE246_9945_2140_BC14_9589485B31D0_58516334_2b0d_4bb8_aa1c_0da7fb0a08c6: '⚡ Leads'!$C$1
Name coeff_c_2CCEE246_9945_2140_BC14_9589485B31D0_954a83f1_e415_4d27_a772_8102e6b33558: '⚡ Leads'!$A$1
Name coeff_c_2CCEE246_9945_2140_BC14_9589485B31D0_987b5bcd_927e_41fb_8970_a5873b232b32: '⚡ Leads'!$B$1
Name coeff_c_2CCEE246_9945_2140_BC14_9589485B31D0_9d1a4a82_19a1_4650_aee1_73e43e206df3: '⚡ Leads'!$D$1
Name coeff_c_344D56EE_B9FC_084D_94CF_57A89FF39BC0_1ce7ea6a_8d9a_476f_8684_125e69f5434a: '⚡ Events'!$C$1
Name coeff_c_344D56EE_B9FC_084D_94CF_57A89FF39BC0_4e562cd5_7fc1_4160_88e6_7c20ee69e91e: '⚡ Events'!$A$1
Name coeff_c_344D56EE_B9FC_084D_94CF_57A89FF39BC0_9032b6c4_5674_4fdc_ba1d_b91c5be50b04: '⚡ Events'!$B$1
Name coeff_c_F6318C9D_BBC0_EF40_B911_3F41904FB1C5_0e358f63_a122_4840_86d6_ac397a19fc14: '⚡ Opportunities'!$B$1
Name coeff_c_F6318C9D_BBC0_EF40_B911_3F41904FB1C5_113d515e_ed67_45e5_8d65_b057dab81bb2: '⚡ Opportunities'!$F$1
Name coeff_c_F6318C9D_BBC0_EF40_B911_3F41904FB1C5_3e86d35e_9779_4adc_b01d_2bb75b6831a8: '⚡ Opportunities'!$E$1
Name coeff_c_F6318C9D_BBC0_EF40_B911_3F41904FB1C5_c2ab382a_94ad_4a4b_ae6b_6de2d30e8c6f: '⚡ Opportunities'!$H$1
Name coeff_c_F6318C9D_BBC0_EF40_B911_3F41904FB1C5_caf804c6_7a8f_4a4e_8ea0_18501cd7ebca: '⚡ Opportunities'!$A$1
Name coeff_c_F6318C9D_BBC0_EF40_B911_3F41904FB1C5_e537817c_237c_438a_aa64_49e98588f5db: '⚡ Opportunities'!$C$1
Name coeff_c_F6318C9D_BBC0_EF40_B911_3F41904FB1C5_ec93bc13_b4de_4d67_b931_521c4f5a2fb6: '⚡ Opportunities'!$G$1
Name coeff_c_F6318C9D_BBC0_EF40_B911_3F41904FB1C5_f9d174cc_4991_4aa3_bb12_8eba789fc966: '⚡ Opportunities'!$D$1
Name coeff_import_id: '⚡ Events'!#REF!
Name coeff_import_id: '⚡ Leads'!#REF!
Name coeff_import_id: '⚡ Opportunities'!#REF!
Name coeff_tpl_name: #REF!

Sheet ⚡ Leads
A1: First Name | B1: Last Name | C1: Company | D1: Created Date | E1: Status
A2: Kase | B2: Perez | C2: Account Jennings981 | D2: =TODAY()-737 -> 45300 | E2: Product Qualified Lead
A3: Sophia | B3: Nguyen | C3: Account Stokes949XX - new - new | D3: =TODAY()-737 -> 45300 | E3: Marketing Qualified Lead
A4: Kayden | B4: Hayes | C4: Account Leonard584X | D4: =TODAY()-737 -> 45300 | E4: Sales Qualified Lead
A5: Karson | B5: Parker | C5: Account Daniels627XX - new | D5: =TODAY()-737 -> 45300 | E5: Opportunity
A6: Faith | B6: Simmons | C6: Account Robbins1143 | D6: =TODAY()-737 -> 45300 | E6: Opportunity
A7: Ryder | B7: Adams | C7: Account Watson1794 | D7: =TODAY()-737 -> 45300 | E7: Sales Qualified Lead
A8: Mia | B8: Thompson | C8: Account Abbott1184X | D8: =TODAY()-737 -> 45300 | E8: Product Qualified Lead
A9: Kade | B9: Martinez | C9: Account Cross1834 - | D9: =TODAY()-737 -> 45300 | E9: Marketing Qualified Lead
A10: Kaia | B10: Hayes | C10: Account Perkins1263 - new | D10: =TODAY()-737 -> 45300 | E10: Opportunity
A11: Cason | B11: Parker | C11: Account Johnson1707XXX | D11: =TODAY()-737 -> 45300 | E11: Lead
A12: Julian | B12: Campbell | C12: Account Cross1834 | D12: =TODAY()-737 -> 45300 | E12: Customer
A13: Ariana | B13: Rivera | C13: Account McCormick23 | D13: =TODAY()-737 -> 45300 | E13: Opportunity
... A61: Christian | B61: Russell | C61: Account Rice1187 - new - new | D61: =TODAY()-737 -> 45300 | E61: Opportunity
A62: Kallie | B62: Murphy | C62: Account Rice1187XX | D62: =TODAY()-707 -> 45330 | E62: Customer
A63: Harper | B63: Rodriguez | C63: Account Olson321XX | D63: =TODAY()-707 -> 45330 | E63: Opportunity
A64: Kenna | B64: Martinez | C64: Account Gordon852XX - new - new | D64: =TODAY()-707 -> 45330 | E64: Opportunity
A65: Jayse | B65: Carter | C65: Account Cobb1406X | D65: =TODAY()-707 -> 45330 | E65: Lead
A66: Kaleigh | B66: Thompson | C66: Account Watson1794X | D66: =TODAY()-707 -> 45330 | E66: Sales Qualified Lead
A67: Jovanni | B67: Bennett | C67: Account Wise361XX - new | D67: =TODAY()-707 -> 45330 | E67: Opportunity
A68: Kai | B68: Adams | C68: Account Malone1334X - new | D68: =TODAY()-707 -> 45330 | E68: Product Qualified Lead
A69: Mackenzie | B69: Diaz | C69: Account Abbott1184 | D69: =TODAY()-707 -> 45330 | E69: Lead
A70: Kaysen | B70: Johnson | C70: Account Abbott1 | D70: =TODAY()-707 -> 45330 | E70: Product Qualified Lead
A71: Andi | B71: Brooks | C71: Account Watson1794XX | D71: =TODAY()-707 -> 45330 | E71: Lead
A72: Desmond | B72: Parker | C72: Account McCormick23 - new | D72: =TODAY()-707 -> 45330 | E72: Customer
A73: Keaton | B73: Perez | C73: Account Hamilton8 - new | D73: =TODAY()-707 -> 45330 | E73: Sales Qualified Lead
... A124: Eli | B124: Ward | C124: Account Klein1486XX | D124: =TODAY()-707 -> 45330 | E124: Product Qualified Lead
A125: Harper | B125: Rodriguez | C125: Account Olson321XX | D125: =TODAY()-676 -> 45361 | E125: Opportunity
A126: Kailani | B126: Scott | C126: Account Release | D126: =TODAY()-676 -> 45361 | E126: Opportunity
A127: Malcolm | B127: Reed | C127: Account Cobb1406XXX | D127: =TODAY()-676 -> 45361 | E127: Opportunity
A128: Kaliyah | B128: Hernandez | C128: McCormick and Sons | D128: =TODAY()-676 -> 45361 | E128: Opportunity
A129: Andrew | B129: Coleman | C129: Account Elliott511X | D129: =TODAY()-676 -> 45361 | E129: Customer
A130: Camille | B130: Rodriguez | C130: Account Spencer1223 - new | D130: =TODAY()-676 -> 45361 | E130: Customer
A131: Karsyn | B131: Bennett | C131: Account Hardy1 - new | D131: =TODAY()-676 -> 45361 | E131: Customer
A132: Luis | B132: Martinez | C132: Account Christensen | D132: =TODAY()-676 -> 45361 | E132: Sales Qualified Lead
A133: Kobe | B133: Campbell | C133: Account Todd162XXX | D133: =TODAY()-676 -> 45361 | E133: Opportunity
A134: Isla | B134: Phillips | C134: Account Conner5XX - new | D134: =TODAY()-676 -> 45361 | E134: Customer
A135: Alana | B135: Butler | C135: Account Olson321XX | D135: =TODAY()-676 -> 45361 | E135: Product Qualified Lead
A136: Luis | B136: Martinez | C136: Account Christensen | D136: =TODAY()-676 -> 45361 | E136: Sales Qualified Lead
... A191: Victoria | B191: Hayes | C191: Account Watson1794X | D191: =TODAY()-676 -> 45361 | E191: Sales Qualified Lead
...

Sheet ⚡ Events
A1: Activity ID | B1: Subject | C1: Created Date
A2: 10000000067 | B2: Diversity Training Workshop with Sarah | C2: =TODAY()-737 -> 45300
A3: 10000000134 | B3: Sales Team Performance Coaching with Amanda | C3: =TODAY()-737 -> 45300
A4: 10000000653 | B4: Environmental Sustainability Initiatives Review with Michelle | C4: =TODAY()-737 -> 45300
A5: 10000000325 | B5: Supply Chain Efficiency Optimization Meeting with Jennifer | C5: =TODAY()-737 -> 45300
A6: 10000000522 | B6: Leadership Development Program Kickoff with Kevin | C6: =TODAY()-737 -> 45300
A7: 10000000067 | B7: Diversity Training Workshop with Sarah | C7: =TODAY()-737 -> 45300
A8: 10000000353 | B8: Creative Thinking and Problem-Solving Workshop with Lisa | C8: =TODAY()-737 -> 45300
A9: 10000000546 | B9: IT Disaster Recovery Simulation Exercise with Daniel | C9: =TODAY()-737 -> 45300
A10: 10000000689 | B10: Sales Performance Metrics Review with Amanda | C10: =TODAY()-737 -> 45300
A11: 10000000227 | B11: Project Kickoff Meeting with Rachel | C11: =TODAY()-737 -> 45300
A12: 10000000148 | B12: Team Collaboration Enhancement Workshop with Emily | C12: =TODAY()-737 -> 45300
A13: 10000000584 | B13: Customer Engagement Metrics Analysis and Improvement with Mark | C13: =TODAY()-737 -> 45300
... A84: 10000000510 | B84: Supplier Performance Evaluation Meeting with Jennifer | C84: =TODAY()-737 -> 45300
A85: 10000000014 | B85: Employee Feedback Roundtable with Brian | C85: =TODAY()-707 -> 45330
A86: 10000000024 | B86: Marketing Campaign Planning Meeting with David | C86: =TODAY()-707 -> 45330
A87: 10000000297 | B87: Market Research Insights Presentation with Laura | C87: =TODAY()-707 -> 45330
A88: 10000000254 | B88: IT System Integration Planning Session with Daniel | C88: =TODAY()-707 -> 45330
A89: 10000000578 | B89: Team Building and Bonding Activities Implementation with Emily | C89: =TODAY()-707 -> 45330
A90: 10000000595 | B90: Financial Risk Assessment and Mitigation Strategy Session with Chris | C90: =TODAY()-707 -> 45330
A91: 10000000266 | B91: Product Portfolio Review Session with Alex | C91: =TODAY()-707 -> 45330
A92: 10000000026 | B92: Financial Forecast Analysis with Chris | C92: =TODAY()-707 -> 45330
A93: 10000000045 | B93: Leadership Roundtable Discussion with Kevin | C93: =TODAY()-707 -> 45330
A94: 10000000632 | B94: Employee Training and Development Forum with Brian | C94: =TODAY()-707 -> 45330
A95: 10000000545 | B95: Corporate Sustainability Reporting Preparation with Michelle | C95: =TODAY()-707 -> 45330
A96: 10000000316 | B96: IT Infrastructure Security Audit Planning with Daniel | C96: =TODAY()-707 -> 45330
... A170: 10000000208 | B170: Budget Planning Session with Chris | C170: =TODAY()-707 -> 45330
A171: 10000000192 | B171: Quarterly Financial Performance Evaluation and Strategy Adjustment with John | C171: =TODAY()-676 -> 45361
A172: 10000000491 | B172: Project Closure and Lessons Learned Session with Rachel | C172: =TODAY()-676 -> 45361
A173: 10000000258 | B173: Financial Efficiency Improvement Discussion with Chris | C173: =TODAY()-676 -> 45361
A174: 10000000599 | B174: Customer Journey Mapping and Experience Design Workshop with Mark | C174: =TODAY()-676 -> 45361
A175: 10000000384 | B175: Customer Engagement Metrics Analysis and Improvement with Mark | C175: =TODAY()-676 -> 45361
A176: 10000000050 | B176: Marketing Analytics Deep Dive with Laura | C176: =TODAY()-676 -> 45361
A177: 10000000370 | B177: Supplier Relationship Enhancement Strategy Meeting with Jennifer | C177: =TODAY()-676 -> 45361
A178: 10000000512 | B178: Market Expansion Strategy Discussion with Laura | C178: =TODAY()-676 -> 45361
A179: 10000000198 | B179: Innovation Pipeline Management and Prioritization Workshop with Lisa | C179: =TODAY()-676 -> 45361
A180: 10000000424 | B180: Marketing Campaign Planning Meeting with David | C180: =TODAY()-676 -> 45361
A181: 10000000642 | B181: Sales Strategy Alignment Session with Jessica | C181: =TODAY()-676 -> 45361
A182: 10000000056 | B182: Team Performance Metrics Analysis with Emily | C182: =TODAY()-676 -> 45361
... A263: 10000000284 | B263: Inclusive Leadership Training Seminar with Sarah | C263: =TODAY()-676 -> 45361
...

Sheet ⚡ Opportunities
A1: Opportunity ID | B1: Name | C1: Created Date | D1: Close Date | E1: Stage | F1: Closed | G1: Won | H1: Amount
A2: 0064T000008ygriQAA | B2: Opportunity for Blair183 | C2: =TODAY()-737 -> 45300 | D2: =TODAY()-722 -> 45315 | E2: Closed Won | F2: TRUE | G2: TRUE | H2: 1650
A3: 0064T000008yguZQAQ | B3: Opportunity for Leonard584X - new | C3: =TODAY()-737 -> 45300 | D3: =TODAY()-727 -> 45310 | E3: Closed Lost | F3: TRUE | G3: FALSE | H3: 2170
A4: 0064T000008yguMQAQ | B4: Opportunity for Brown1230XX - new | C4: =TODAY()-737 -> 45300 | D4: =TODAY()-726 -> 45311 | E4: Closed Won | F4: TRUE | G4: TRUE | H4: 2110
A5: 0064T000008yguyQAA | B5: Opportunity for Swanson1068X | C5: =TODAY()-737 -> 45300 | E5: Prospecting | F5: FALSE | G5: FALSE | H5: 240
A6: 0064T000002kJaHQAU | B6: Opportunity for McCormick23 - new | C6: =TODAY()-737 -> 45300 | D6: =TODAY()-719 -> 45318 | E6: Closed Won | F6: TRUE | G6: TRUE | H6: 130
A7: 0064T000002kJbPQAU | B7: Opportunity for Hardy1507XX - new | C7: =TODAY()-737 -> 45300 | D7: =TODAY()-725 -> 45312 | E7: Closed Won | F7: TRUE | G7: TRUE | H7: 1280
A8: 0064T000008ygubQAA | B8: Opportunity for Brown1230XX | C8: =TODAY()-737 -> 45300 | D8: =TODAY()-719 -> 45318 | E8: Closed Won | F8: TRUE | G8: TRUE | H8: 1580
A9: 0064T000008ygstQAA | B9: Opportunity for Santiago1975X - new | C9: =TODAY()-737 -> 45300 | D9: =TODAY()-707 -> 45330 | E9: Closed Won | F9: TRUE | G9: TRUE | H9: 1310
A10: 0064T000002kJYFQA2 | B10: Opportunity for Armstrong600 - new | C10: =TODAY()-737 -> 45300 | D10: =TODAY()-727 -> 45310 | E10: Closed Won | F10: TRUE | G10: TRUE | H10: 2270
A11: 0064T000008ygrWQAQ | B11: Opportunity for Todd1938 | C11: =TODAY()-737 -> 45300 | E11: Prospecting | F11: FALSE | G11: FALSE | H11: 2500
A12: 0064T000008ygrgQAA | B12: Opportunity for Flowers1427X | C12: =TODAY()-737 -> 45300 | D12: =TODAY()-717 -> 45320 | E12: Closed Won | F12: TRUE | G12: TRUE | H12: 2330
A13: 0064T000008ygvkQAA | B13: Opportunity for Abbott1184XX | C13: =TODAY()-737 -> 45300 | D13: =TODAY()-726 -> 45311 | E13: Closed Lost | F13: TRUE | G13: FALSE | H13: 640
A14: 0064T000008ygrvQAA | B14: Opportunity for Butler33X - new | C14: =TODAY()-737 -> 45300 | D14: =TODAY()-721 -> 45316 | E14: Closed Won | F14: TRUE | G14: TRUE | H14: 6360
A15: 0064T000008ygq0QAA | B15: Opportunity for Moss1820XX | C15: =TODAY()-737 -> 45300 | D15: =TODAY()-718 -> 45319 | E15: Closed Lost | F15: TRUE | G15: FALSE | H15: 1490
A16: 0064T000008ygvVQAQ | B16: Opportunity for Carol | C16: =TODAY()-737 -> 45300 | D16: =TODAY()-718 -> 45319 | E16: Closed Won | F16: TRUE | G16: TRUE | H16: 800
A17: 0064T000008ygspQAA | B17: Opportunity for Rodriquez958X - new | C17: =TODAY()-737 -> 45300 | E17: Prospecting | F17: FALSE | G17: FALSE | H17: 1510
A18: 0064T000008ygvqQAA | B18: Opportunity for Daniels627XX - new | C18: =TODAY()-737 -> 45300 | D18: =TODAY()-719 -> 45318 | E18: Closed Lost | F18: TRUE | G18: FALSE | H18: 310
A19: 0064T000002kJYgQAM | B19: Opportunity for Todd162X - new | C19: =TODAY()-737 -> 45300 | D19: =TODAY()-720 -> 45317 | E19: Closed Won | F19: TRUE | G19: TRUE | H19: 1210
A20: 0064T000008ygrvQAA | B20: Opportunity for Butler33X - new | C20: =TODAY()-737 -> 45300 | D20: =TODAY()-716 -> 45321 | E20: Closed Won | F20: TRUE | G20: TRUE | H20: 6360
A21: 0064T000008yguGQAQ | B21: Opportunity for Olson321X - new | C21: =TODAY()-737 -> 45300 | D21: =TODAY()-713 -> 45324 | E21: Closed Won | F21: TRUE | G21: TRUE | H21: 820
A22: 0064T000008ygtgQAA | B22: Opportunity for Bennett62XX | C22: =TODAY()-737 -> 45300 | E22: Perception Analysis | F22: FALSE | G22: FALSE | H22: 1450
A23: 0064T000008yguSQAQ | B23: Opportunity for McCormick23X - new | C23: =TODAY()-737 -> 45300 | D23: =TODAY()-710 -> 45327 | E23: Closed Won | F23: TRUE | G23: TRUE | H23: 760
A24: 0064T000008ygupQAA | B24: Opportunity for Phelps205 | C24: =TODAY()-737 -> 45300 | D24: =TODAY()-708 -> 45329 | E24: Closed Lost | F24: TRUE | G24: FALSE | H24: 1320
A25: 0064T000008ygvyQAA | B25: Opportunity for Klein1486XXX - new | C25: =TODAY()-737 -> 45300 | E25: Proposal/Price Quote | F25: FALSE | G25: FALSE | H25: 740
A26: 0064T000008ygvVQAQ | B26: Opportunity for Nguyen1971XX - new | C26: =TODAY()-737 -> 45300 | D26: =TODAY()-724 -> 45313 | E26: Closed Won | F26: TRUE | G26: TRUE | H26: 2060
A27: 0064T000008yguPQAQ | B27: Opportunity for Murphy1963 - new | C27: =TODAY()-737 -> 45300 | D27: =TODAY()-707 -> 45330 | E27: Closed Won | F27: TRUE | G27: TRUE | H27: 640
A28: 0064T000008ygvEQAQ | B28: Opportunity for Barker1602XX - new | C28: =TODAY()-737 -> 45300 | D28: =TODAY()-717 -> 45320 | E28: Closed Won | F28: TRUE | G28: TRUE | H28: 2430
A29: 0064T000008ygt4QAA | B29: Opportunity for Todd162XX | C29: =TODAY()-737 -> 45300 | D29: =TODAY()-727 -> 45310 | E29: Closed Won | F29: TRUE | G29: TRUE | H29: 730
A30: 0064T000008ygwMQAQ | B30: Opportunity for Robbins1143XX | C30: =TODAY()-737 -> 45300 | D30: =TODAY()-723 -> 45314 | E30: Closed Won | F30: TRUE | G30: TRUE | H30: 390
A31: 0064T000008ygsSQAQ | B31: Opportunity for Andrews1792 | C31: =TODAY()-737 -> 45300 | D31: =TODAY()-709 -> 45328 | E31: Closed Lost | F31: TRUE | G31: FALSE | H31: 850
A32: 0064T000008ygtFQAQ | B32: Opportunity for Robbins1143X | C32: =TODAY()-737 -> 45300 | D32: =TODAY()-708 -> 45329 | E32: Closed Lost | F32: TRUE | G32: FALSE | H32: 1740
A33: 0064T000008ygvWQAQ | B33: Opportunity for Alvarez1088XXX | C33: =TODAY()-737 -> 45300 | D33: =TODAY()-724 -> 45313 | E33: Closed Lost | F33: TRUE | G33: FALSE | H33: 580
A34: 0064T000002kJXdQAM | B34: Opportunity for Banks821XX - new | C34: =TODAY()-737 -> 45300 | D34: =TODAY()-712 -> 45325 | E34: Closed Lost | F34: TRUE | G34: FALSE | H34: 890
A35: 0064T000008ygsAQAQ | B35: Opportunity for Joseph722 - new | C35: =TODAY()-737 -> 45300 | E35: Prospecting | F35: FALSE | G35: FALSE | H35: 1170
A36: 0064T000008ygspQAA | B36: Opportunity for Rodriquez958X - new | C36: =TODAY()-737 -> 45300 | E36: Prospecting | F36: FALSE | G36: FALSE | H36: 1510
A37: 0064T000008ygutQAA | B37: Opportunity for Olson321 - new | C37: =TODAY()-737 -> 45300 | D37: =TODAY()-720 -> 45317 | E37: Closed Won | F37: TRUE | G37: TRUE | H37: 1110
A38: 0064T000008yguwQAA | B38: Opportunity for Wilkins1370XX - new | C38: =TODAY()-737 -> 45300 | E38: Negotiation/Review | F38: FALSE | G38: FALSE | H38: 1040
A39: 0064T000008ygspQAA | B39: Opportunity for Moore962X | C39: =TODAY()-737 -> 45300 | E39: Qualification | F39: FALSE | G39: FALSE | H39: 740
A40: 0064T000008ygtJQAQ | B40: Opportunity for Chandler1816XX - new | C40: =TODAY()-737 -> 45300 | D40: =TODAY()-723 -> 45314 | E40: Closed Lost | F40: TRUE | G40: FALSE | H40: 150
...

Sheet 📊 12-Month Sales Forecast Dash
AA1: Linear Regression | AH1: Moving Average | AO1: Simple Exponential Smoothing
R2: Month Year | S2: Acquired Leads | T2: Meetings Booked | U2: New Opportunities | V2: # Projected Closed/Won | W2: $ Forecasted Revenue | X2: Total Revenue | Y2: Label | AA2: Month Year | AB2: Acquired Leads | AC2: Meetings Booked | AD2: New Opportunities | AE2: Closed/Won | AF2: New Revenue per Month | AH2: Month Year | AI2: Acquired Leads | AJ2: Meetings Booked | AK2: New Opportunities | AL2: Closed/Won | AM2: New Revenue per Month | AO2: Month Year | AP2: Acquired Leads | AQ2: Meetings Booked | AR2: New Opportunities | AS2: Closed/Won | AT2: New Revenue per Month | AU2: =AA1 -> Linear Regression
B3: Salesforce 12-Month Sales Forecast Dashboard | R3: =D14 -> 46023 | S3: {=IF(C6=AA1,AB27:AF50,IF(C6=AH1,AI27:AM50,IF(C6=AO1,AP27:AT50,)))} -> 88.979183 | T3: 118.47633 | U3: 110.40166 | V3: 61.237095 | W3: 99793.517 | X3: {=_xlfn.SCAN(0, W3:W26, _xlfn.LAMBDA(_xlpm.x,_xlpm.y, _xlpm.x + _xlpm.y))} -> 99793.517 | Y3: {=_xlfn.BYROW(W3:W26, _xlfn.LAMBDA(_xlpm.x, IF(_xlpm.x = "", "", "$" & TEXT(_xlpm.x, IF(_xlpm.x >= 1000000, "#,###,,", IF(_xlpm.x >= 1000, "#,###,", "#,###")) ) & IF(_xlpm.x >= 1000000, "M", IF(_xlpm.x >= 1000, "k", "")) ) ))} -> $100k | AA3: =EDATE(AA4,-1) -> 45292 | AB3: =COUNTIFS('⚡ Leads'!D:D,">="&AA3,'⚡ Leads'!D:D,"<"&EDATE(AA3,1)) -> 60 | AC3: =COUNTIFS('⚡ Events'!C:C,">="&AA3,'⚡ Events'!C:C,"<"&EDATE(AA3,1)) -> 83 | AD3: =COUNTIFS('⚡ Opportunities'!C:C,">="&AA3,'⚡ Opportunities'!C:C,"<"&EDATE(AA3,1)) -> 74 | AE3: =COUNTIFS('⚡ Opportunities'!C:C,">="&AA3,'⚡ Opportunities'!C:C,"<"&EDATE(AA3,1),'⚡ Opportunities'!F:F,TRUE,'⚡ Opportunities'!G:G,TRUE) -> 42 | AF3: =SUMIFS('⚡ Opportunities'!H:H,'⚡ Opportunities'!C:C,">="&AA3,'⚡ Opportunities'!C:C,"<"&EDATE(AA3,1),'⚡ Opportunities'!F:F,TRUE,'⚡ Opportunities'!G:G,TRUE) -> 71170 | AH3: =EDATE(AH4,-1) -> 45292 | AI3: =COUNTIFS('⚡ Leads'!D:D,">="&AA3,'⚡ Leads'!D:D,"<"&EDATE(AA3,1)) -> 60 | AJ3: =COUNTIFS('⚡ Events'!C:C,">="&AA3,'⚡ Events'!C:C,"<"&EDATE(AA3,1)) -> 83 | AK3: =COUNTIFS('⚡ Opportunities'!C:C,">="&AA3,'⚡ Opportunities'!C:C,"<"&EDATE(AA3,1)) -> 74 | AL3: =COUNTIFS('⚡ Opportunities'!C:C,">="&AA3,'⚡ Opportunities'!C:C,"<"&EDATE(AA3,1),'⚡ Opportunities'!F:F,TRUE,'⚡ Opportunities'!G:G,TRUE) -> 42 | AM3: =SUMIFS('⚡ Opportunities'!H:H,'⚡ Opportunities'!C:C,">="&AA3,'⚡ Opportunities'!C:C,"<"&EDATE(AA3,1),'⚡ Opportunities'!F:F,TRUE,'⚡ Opportunities'!G:G,TRUE) -> 71170 | AO3: =EDATE(AO4,-1) -> 45231 | AP3: =COUNTIFS('⚡ Leads'!D:D,">="&AA3,'⚡ Leads'!D:D,"<"&EDATE(AA3,1)) -> 60 | AQ3: =COUNTIFS('⚡ Events'!C:C,">="&AA3,'⚡ Events'!C:C,"<"&EDATE(AA3,1)) -> 83 | AR3: =COUNTIFS('⚡ Opportunities'!C:C,">="&AA3,'⚡ Opportunities'!C:C,"<"&EDATE(AA3,1)) -> 74 | AS3: =COUNTIFS('⚡ Opportunities'!C:C,">="&AA3,'⚡ Opportunities'!C:C,"<"&EDATE(AA3,1),'⚡ Opportunities'!F:F,TRUE,'⚡ Opportunities'!G:G,TRUE) -> 42 | AT3: =SUMIFS('⚡ Opportunities'!H:H,'⚡ Opportunities'!C:C,">="&AA3,'⚡ Opportunities'!C:C,"<"&EDATE(AA3,1),'⚡ Opportunities'!F:F,TRUE,'⚡ Opportunities'!G:G,TRUE) -> 71170 | AU3: =AH1 -> Moving Average
R4: {=IFERROR(_xlfn.BYROW(_xlfn.SEQUENCE(23),_xlfn.LAMBDA(_xlpm.x,IFERROR(DATE(YEAR(R3),MONTH(R3)+_xlpm.x,1),"Month "&(_xlpm.x+1)))),"")} -> 46054 | S4: 89.149743 | T4: 118.71602 | U4: 110.60535 | V4: 61.192974 | W4: 99950.892 | X4: 199744.41 | Y4: $100k | AA4: =EDATE(AA5,-1) -> 45323 | AB4: =COUNTIFS('⚡ Leads'!D:D,">="&AA4,'⚡ Leads'!D:D,"<"&EDATE(AA4,1)) -> 63 | AC4: =COUNTIFS('⚡ Events'!C:C,">="&AA4,'⚡ Events'!C:C,"<"&EDATE(AA4,1)) -> 86 | AD4: =COUNTIFS('⚡ Opportunities'!C:C,">="&AA4,'⚡ Opportunities'!C:C,"<"&EDATE(AA4,1)) -> 80 | AE4: =COUNTIFS('⚡ Opportunities'!C:C,">="&AA4,'⚡ Opportunities'!C:C,"<"&EDATE(AA4,1),'⚡ Opportunities'!F:F,TRUE,'⚡ Opportunities'!G:G,TRUE) -> 40 | AF4: =SUMIFS('⚡ Opportunities'!H:H,'⚡ Opportunities'!C:C,">="&AA4,'⚡ Opportunities'!C:C,"<"&EDATE(AA4,1),'⚡ Opportunities'!F:F,TRUE,'⚡ Opportunities'!G:G,TRUE) -> 70960 | AH4: =EDATE(AH5,-1) -> 45323 | AI4: =COUNTIFS('⚡ Leads'!D:D,">="&AA4,'⚡ Leads'!D:D,"<"&EDATE(AA4,1)) -> 63 | AJ4: =COUNTIFS('⚡ Events'!C:C,">="&AA4,'⚡ Events'!C:C,"<"&EDATE(AA4,1)) -> 86 | AK4: =COUNTIFS('⚡ Opportunities'!C:C,">="&AA4,'⚡ Opportunities'!C:C,"<"&EDATE(AA4,1)) -> 80 | AL4: =COUNTIFS('⚡ Opportunities'!C:C,">="&AA4,'⚡ Opportunities'!C:C,"<"&EDATE(AA4,1),'⚡ Opportunities'!F:F,TRUE,'⚡ Opportunities'!G:G,TRUE) -> 40 | AM4: =SUMIFS('⚡ Opportunities'!H:H,'⚡ Opportunities'!C:C,">="&AA4,'⚡ Opportunities'!C:C,"<"&EDATE(AA4,1),'⚡ Opportunities'!F:F,TRUE,'⚡ Opportunities'!G:G,TRUE) -> 70960 | AO4: =EDATE(AO5,-1) -> 45261 | AP4: =COUNTIFS('⚡ Leads'!D:D,">="&AA4,'⚡ Leads'!D:D,"<"&EDATE(AA4,1)) -> 63 | AQ4: =COUNTIFS('⚡ Events'!C:C,">="&AA4,'⚡ Events'!C:C,"<"&EDATE(AA4,1)) -> 86 | AR4: =COUNTIFS('⚡ Opportunities'!C:C,">="&AA4,'⚡ Opportunities'!C:C,"<"&EDATE(AA4,1)) -> 80 | AS4: =COUNTIFS('⚡ Opportunities'!C:C,">="&AA4,'⚡ Opportunities'!C:C,"<"&EDATE(AA4,1),'⚡ Opportunities'!F:F,TRUE,'⚡ Opportunities'!G:G,TRUE) -> 40 | AT4: =SUMIFS('⚡ Opportunities'!H:H,'⚡ Opportunities'!C:C,">="&AA4,'⚡ Opportunities'!C:C,"<"&EDATE(AA4,1),'⚡ Opportunities'!F:F,TRUE,'⚡ Opportunities'!G:G,TRUE) -> 70960 | AU4: =AO1 -> Simple Exponential Smoothing
R5: 46082 | S5: 89.417364 | T5: 119.05736 | U5: 110.9519 | V5: 61.183476 | W5: 99972.213 | X5: 299716.62 | Y5: $100k | AA5: =EDATE(AA6,-1) -> 45352 | AB5: =COUNTIFS('⚡ Leads'!D:D,">="&AA5,'⚡ Leads'!D:D,"<"&EDATE(AA5,1)) -> 67 | AC5: =COUNTIFS('⚡ Events'!C:C,">="&AA5,'⚡ Events'!C:C,"<"&EDATE(AA5,1)) -> 93 | AD5: =COUNTIFS('⚡ Opportunities'!C:C,">="&AA5,'⚡ Opportunities'!C:C,"<"&EDATE(AA5,1)) -> 84 | AE5: =COUNTIFS('⚡ Opportunities'!C:C,">="&AA5,'⚡ Opportunities'!C:C,"<"&EDATE(AA5,1),'⚡ Opportunities'!F:F,TRUE,'⚡ Opportunities'!G:G,TRUE) -> 44 | AF5: =SUMIFS('⚡ Opportunities'!H:H,'⚡ Opportunities'!C:C,">="&AA5,'⚡ Opportunities'!C:C,"<"&EDATE(AA5,1),'⚡ Opportunities'!F:F,TRUE,'⚡ Opportunities'!G:G,TRUE) -> 49640 | AH5: =EDATE(AH6,-1) -> 45352 | AI5: =COUNTIFS('⚡ Leads'!D:D,">="&AA5,'⚡ Leads'!D:D,"<"&EDATE(AA5,1)) -> 67 | AJ5: =COUNTIFS('⚡ Events'!C:C,">="&AA5,'⚡ Events'!C:C,"<"&EDATE(AA5,1)) -> 93 | AK5: =COUNTIFS('⚡ Opportunities'!C:C,">="&AA5,'⚡ Opportunities'!C:C,"<"&EDATE(AA5,1)) -> 84 | AL5: =COUNTIFS('⚡ Opportunities'!C:C,">="&AA5,'⚡ Opportunities'!C:C,"<"&EDATE(AA5,1),'⚡ Opportunities'!F:F,TRUE,'⚡ Opportunities'!G:G,TRUE) -> 44 | AM5: =SUMIFS('⚡ Opportunities'!H:H,'⚡ Opportunities'!C:C,">="&AA5,'⚡ Opportunities'!C:C,"<"&EDATE(AA5,1),'⚡ Opportunities'!F:F,TRUE,'⚡ Opportunities'!G:G,TRUE) -> 49640 | AO5: =EDATE(AO6,-1) -> 45292 | AP5: =COUNTIFS('⚡ Leads'!D:D,">="&AA5,'⚡ Leads'!D:D,"<"&EDATE(AA5,1)) -> 67 | AQ5: =COUNTIFS('⚡ Events'!C:C,">="&AA5,'⚡ Events'!C:C,"<"&EDATE(AA5,1)) -> 93 | AR5: =COUNTIFS('⚡ Opportunities'!C:C,">="&AA5,'⚡ Opportunities'!C:C,"<"&EDATE(AA5,1)) -> 84 | AS5: =COUNTIFS('⚡ Opportunities'!C:C,">="&AA5,'⚡ Opportunities'!C:C,"<"&EDATE(AA5,1),'⚡ Opportunities'!F:F,TRUE,'⚡ Opportunities'!G:G,TRUE) -> 44 | AT5: =SUMIFS('⚡ Opportunities'!H:H,'⚡ Opportunities'!C:C,">="&AA5,'⚡ Opportunities'!C:C,"<"&EDATE(AA5,1),'⚡ Opportunities'!F:F,TRUE,'⚡ Opportunities'!G:G,TRUE) -> 49640
B6: Forecast Method: | C6: Simple Exponential Smoothing | F6: =IF(C6=AO1,"Smoothing Parameter:","") -> Smoothing Parameter: | G6: 0.8 | H6: =IF(C6=AH1,"No. of Months to Consider:","") | I6: 12 | R6: 46113 | S6: 89.718724 | T6: 119.42523 | U6: 111.34622 | V6: 61.295684 | W6: 100038.59 | X6: 399755.21 | Y6: $100k | AA6: =EDATE(AA7,-1) -> 45383 | AB6: =COUNTIFS('⚡ Leads'!D:D,">="&AA6,'⚡ Leads'!D:D,"<"&EDATE(AA6,1)) -> 71 | AC6: =COUNTIFS('⚡ Events'!C:C,">="&AA6,'⚡ Events'!C:C,"<"&EDATE(AA6,1)) -> 97 | AD6: =COUNTIFS('⚡ Opportunities'!C:C,">="&AA6,'⚡ Opportunities'!C:C,"<"&EDATE(AA6,1)) -> 86 | AE6: =COUNTIFS('⚡ Opportunities'!C:C,">="&AA6,'⚡ Opportunities'!C:C,"<"&EDATE(AA6,1),'⚡ Opportunities'!F:F,TRUE,'⚡ Opportunities'!G:G,TRUE) -> 39 | AF6: =SUMIFS('⚡ Opportunities'!H:H,'⚡ Opportunities'!C:C,">="&AA6,'⚡ Opportunities'!C:C,"<"&EDATE(AA6,1),'⚡ Opportunities'!F:F,TRUE,'⚡ Opportunities'!G:G,TRUE) -> 54800 | AH6: =EDATE(AH7,-1) -> 45383 | AI6: =COUNTIFS('⚡ Leads'!D:D,">="&AA6,'⚡ Leads'!D:D,"<"&EDATE(AA6,1)) -> 71 | AJ6: =COUNTIFS('⚡ Events'!C:C,">="&AA6,'⚡ Events'!C:C,"<"&EDATE(AA6,1)) -> 97 | AK6: =COUNTIFS('⚡ Opportunities'!C:C,">="&AA6,'⚡ Opportunities'!C:C,"<"&EDATE(AA6,1)) -> 86 | AL6: =COUNTIFS('⚡ Opportunities'!C:C,">="&AA6,'⚡ Opportunities'!C:C,"<"&EDATE(AA6,1),'⚡ Opportunities'!F:F,TRUE,'⚡ Opportunities'!G:G,TRUE) -> 39 | AM6: =SUMIFS('⚡ Opportunities'!H:H,'⚡ Opportunities'!C:C,">="&AA6,'⚡ Opportunities'!C:C,"<"&EDATE(AA6,1),'⚡ Opportunities'!F:F,TRUE,'⚡ Opportunities'!G:G,TRUE) -> 54800 | AO6: =EDATE(AO7,-1) -> 45323 | AP6: =COUNTIFS('⚡ Leads'!D:D,">="&AA6,'⚡ Leads'!D:D,"<"&EDATE(AA6,1)) -> 71 | AQ6: =COUNTIFS('⚡ Events'!C:C,">="&AA6,'⚡ Events'!C:C,"<"&EDATE(AA6,1)) -> 97 | AR6: =COUNTIFS('⚡ Opportunities'!C:C,">="&AA6,'⚡ Opportunities'!C:C,"<"&EDATE(AA6,1)) -> 86 | AS6: =COUNTIFS('⚡ Opportunities'!C:C,">="&AA6,'⚡ Opportunities'!C:C,"<"&EDATE(AA6,1),'⚡ Opportunities'!F:F,TRUE,'⚡ Opportunities'!G:G,TRUE) -> 39 | AT6: =SUMIFS('⚡ Opportunities'!H:H,'⚡ Opportunities'!C:C,">="&AA6,'⚡ Opportunities'!C:C,"<"&EDATE(AA6,1),'⚡ Opportunities'!F:F,TRUE,'⚡ Opportunities'!G:G,TRUE) -> 54800
C7: =IF(C6=AA1,"***The method utilizes a minimum of two years' worth of historical data. Use of this method with less than two years of data may result in inaccurate or unreliable forecasts.", IF(C6=AH1,"***This method averages data over the past five months, and assumes consistent patterns over time. Limited or highly fluctuating data may not reflect actual trends accurately,", IF(C6=AO1,"*** This method uses a smoothing parameter that assigns more weight to more recent data. While effective for steady trends, its accuracy may be compromised if the dataset is too short or contains irregular patterns.", "***Select forecasting method."))) -> *** This method uses a smoothing parameter that assigns more weight to more recent data. While effective for steady trends, its accuracy may be compromised if the dataset is too short or contains irregular patterns. | R7: 46143 | S7: 90.003562 | T7: 119.78335 | U7: 111.73633 | V7: 61.400693 | W7: 99437.794 | X7: 499193.01 | Y7: $99k | AA7: =EDATE(AA8,-1) -> 45413 | AB7: =COUNTIFS('⚡ Leads'!D:D,">="&AA7,'⚡ Leads'!D:D,"<"&EDATE(AA7,1)) -> 75 | AC7: =COUNTIFS('⚡ Events'!C:C,">="&AA7,'⚡ Events'!C:C,"<"&EDATE(AA7,1)) -> 100 | AD7: =COUNTIFS('⚡ Opportunities'!C:C,">="&AA7,'⚡ Opportunities'!C:C,"<"&EDATE(AA7,1)) -> 93 | AE7: =COUNTIFS('⚡ Opportunities'!C:C,">="&AA7,'⚡ Opportunities'!C:C,"<"&EDATE(AA7,1),'⚡ Opportunities'!F:F,TRUE,'⚡ Opportunities'!G:G,TRUE) -> 42 | AF7: =SUMIFS('⚡ Opportunities'!H:H,'⚡ Opportunities'!C:C,">="&AA7,'⚡ Opportunities'!C:C,"<"&EDATE(AA7,1),'⚡ Opportunities'!F:F,TRUE,'⚡ Opportunities'!G:G,TRUE) -> 54350 | AH7: =EDATE(AH8,-1) -> 45413 | AI7: =COUNTIFS('⚡ Leads'!D:D,">="&AA7,'⚡ Leads'!D:D,"<"&EDATE(AA7,1)) -> 75 | AJ7: =COUNTIFS('⚡ Events'!C:C,">="&AA7,'⚡ Events'!C:C,"<"&EDATE(AA7,1)) -> 100 | AK7: =COUNTIFS('⚡ Opportunities'!C:C,">="&AA7,'⚡ Opportunities'!C:C,"<"&EDATE(AA7,1)) -> 93 | AL7: =COUNTIFS('⚡ Opportunities'!C:C,">="&AA7,'⚡ Opportunities'!C:C,"<"&EDATE(AA7,1),'⚡ Opportunities'!F:F,TRUE,'⚡ Opportunities'!G:G,TRUE) -> 42 | AM7: =SUMIFS('⚡ Opportunities'!H:H,'⚡ Opportunities'!C:C,">="&AA7,'⚡ Opportunities'!C:C,"<"&EDATE(AA7,1),'⚡ Opportunities'!F:F,TRUE,'⚡ Opportunities'!G:G,TRUE) -> 54350 | AO7: =EDATE(AO8,-1) -> 45352 | AP7: =COUNTIFS('⚡ Leads'!D:D,">="&AA7,'⚡ Leads'!D:D,"<"&EDATE(AA7,1)) -> 75 | AQ7: =COUNTIFS('⚡ Events'!C:C,">="&AA7,'⚡ Events'!C:C,"<"&EDATE(AA7,1)) -> 100 | AR7: =COUNTIFS('⚡ Opportunities'!C:C,">="&AA7,'⚡ Opportunities'!C:C,"<"&EDATE(AA7,1)) -> 93 | AS7: =COUNTIFS('⚡ Opportunities'!C:C,">="&AA7,'⚡ Opportunities'!C:C,"<"&EDATE(AA7,1),'⚡ Opportunities'!F:F,TRUE,'⚡ Opportunities'!G:G,TRUE) -> 42 | AT7: =SUMIFS('⚡ Opportunities'!H:H,'⚡ Opportunities'!C:C,">="&AA7,'⚡ Opportunities'!C:C,"<"&EDATE(AA7,1),'⚡ Opportunities'!F:F,TRUE,'⚡ Opportunities'!G:G,TRUE) -> 54350
R8: 46174 | S8: 90.266768 | T8: 120.09083 | U8: 112.10414 | V8: 61.642356 | W8: 99384.072 | X8: 598577.08 | Y8: $99k | AA8: =EDATE(AA9,-1) -> 45444 | AB8: =COUNTIFS('⚡ Leads'!D:D,">="&AA8,'⚡ Leads'!D:D,"<"&EDATE(AA8,1)) -> 72 | AC8: =COUNTIFS('⚡ Events'!C:C,">="&AA8,'⚡ Events'!C:C,"<"&EDATE(AA8,1)) -> 98 | AD8: =COUNTIFS('⚡ Opportunities'!C:C,">="&AA8,'⚡ Opportunities'!C:C,"<"&EDATE(AA8,1)) -> 90 | AE8: =COUNTIFS('⚡ Opportunities'!C:C,">="&AA8,'⚡ Opportunities'!C:C,"<"&EDATE(AA8,1),'⚡ Opportunities'!F:F,TRUE,'⚡ Opportunities'!G:G,TRUE) -> 60 | AF8: =SUMIFS('⚡ Opportunities'!H:H,'⚡ Opportunities'!C:C,">="&AA8,'⚡ Opportunities'!C:C,"<"&EDATE(AA8,1),'⚡ Opportunities'!F:F,TRUE,'⚡ Opportunities'!G:G,TRUE) -> 122640 | AH8: =EDATE(AH9,-1) -> 45444 | AI8: =COUNTIFS('⚡ Leads'!D:D,">="&AA8,'⚡ Leads'!D:D,"<"&EDATE(AA8,1)) -> 72 | AJ8: =COUNTIFS('⚡ Events'!C:C,">="&AA8,'⚡ Events'!C:C,"<"&EDATE(AA8,1)) -> 98 | AK8: =COUNTIFS('⚡ Opportunities'!C:C,">="&AA8,'⚡ Opportunities'!C:C,"<"&EDATE(AA8,1)) -> 90 | AL8: =COUNTIFS('⚡ Opportunities'!C:C,">="&AA8,'⚡ Opportunities'!C:C,"<"&EDATE(AA8,1),'⚡ Opportunities'!F:F,TRUE,'⚡ Opportunities'!G:G,TRUE) -> 60 | AM8: =SUMIFS('⚡ Opportunities'!H:H,'⚡ Opportunities'!C:C,">="&AA8,'⚡ Opportunities'!C:C,"<"&EDATE(AA8,1),'⚡ Opportunities'!F:F,TRUE,'⚡ Opportunities'!G:G,TRUE) -> 122640 | AO8: =EDATE(AO9,-1) -> 45383 | AP8: =COUNTIFS('⚡ Leads'!D:D,">="&AA8,'⚡ Leads'!D:D,"<"&EDATE(AA8,1)) -> 72 | AQ8: =COUNTIFS('⚡ Events'!C:C,">="&AA8,'⚡ Events'!C:C,"<"&EDATE(AA8,1)) -> 98 | AR8: =COUNTIFS('⚡ Opportunities'!C:C,">="&AA8,'⚡ Opportunities'!C:C,"<"&EDATE(AA8,1)) -> 90 | AS8: =COUNTIFS('⚡ Opportunities'!C:C,">="&AA8,'⚡ Opportunities'!C:C,"<"&EDATE(AA8,1),'⚡ Opportunities'!F:F,TRUE,'⚡ Opportunities'!G:G,TRUE) -> 60 | AT8: =SUMIFS('⚡ Opportunities'!H:H,'⚡ Opportunities'!C:C,">="&AA8,'⚡ Opportunities'!C:C,"<"&EDATE(AA8,1),'⚡ Opportunities'!F:F,TRUE,'⚡ Opportunities'!G:G,TRUE) -> 122640
R9: 46204 | S9: 90.480472 | T9: 120.34964 | U9: 112.41139 | V9: 61.902067 | W9: 99638.671 | X9: 698215.75 | Y9: $100k | AA9: =EDATE(AA10,-1) -> 45474 | AB9: =COUNTIFS('⚡ Leads'!D:D,">="&AA9,'⚡ Leads'!D:D,"<"&EDATE(AA9,1)) -> 77 | AC9: =COUNTIFS('⚡ Events'!C:C,">="&AA9,'⚡ Events'!C:C,"<"&EDATE(AA9,1)) -> 104 | AD9: =COUNTIFS('⚡ Opportunities'!C:C,">="&AA9,'⚡ Opportunities'!C:C,"<"&EDATE(AA9,1)) -> 96 | AE9: =COUNTIFS('⚡ Opportunities'!C:C,">="&AA9,'⚡ Opportunities'!C:C,"<"&EDATE(AA9,1),'⚡ Opportunities'!F:F,TRUE,'⚡ Opportunities'!G:G,TRUE) -> 55 | AF9: =SUMIFS('⚡ Opportunities'!H:H,'⚡ Opportunities'!C:C,">="&AA9,'⚡ Opportunities'!C:C,"<"&EDATE(AA9,1),'⚡ Opportunities'!F:F,TRUE,'⚡ Opportunities'!G:G,TRUE) -> 79860 | AH9: =EDATE(AH10,-1) -> 45474 | AI9: =COUNTIFS('⚡ Leads'!D:D,">="&AA9,'⚡ Leads'!D:D,"<"&EDATE(AA9,1)) -> 77 | AJ9: =COUNTIFS('⚡ Events'!C:C,">="&AA9,'⚡ Events'!C:C,"<"&EDATE(AA9,1)) -> 104 | AK9: =COUNTIFS('⚡ Opportunities'!C:C,">="&AA9,'⚡ Opportunities'!C:C,"<"&EDATE(AA9,1)) -> 96 | AL9: =COUNTIFS('⚡ Opportunities'!C:C,">="&AA9,'⚡ Opportunities'!C:C,"<"&EDATE(AA9,1),'⚡ Opportunities'!F:F,TRUE,'⚡ Opportunities'!G:G,TRUE) -> 55 | AM9: =SUMIFS('⚡ Opportunities'!H:H,'⚡ Opportunities'!C:C,">="&AA9,'⚡ Opportunities'!C:C,"<"&EDATE(AA9,1),'⚡ Opportunities'!F:F,TRUE,'⚡ Opportunities'!G:G,TRUE) -> 79860 | AO9: =EDATE(AO10,-1) -> 45413 | AP9: =COUNTIFS('⚡ Leads'!D:D,">="&AA9,'⚡ Leads'!D:D,"<"&EDATE(AA9,1)) -> 77 | AQ9: =COUNTIFS('⚡ Events'!C:C,">="&AA9,'⚡ Events'!C:C,"<"&EDATE(AA9,1)) -> 104 | AR9: =COUNTIFS('⚡ Opportunities'!C:C,">="&AA9,'⚡ Opportunities'!C:C,"<"&EDATE(AA9,1)) -> 96 | AS9: =COUNTIFS('⚡ Opportunities'!C:C,">="&AA9,'⚡ Opportunities'!C:C,"<"&EDATE(AA9,1),'⚡ Opportunities'!F:F,TRUE,'⚡ Opportunities'!G:G,TRUE) -> 55 | AT9: =SUMIFS('⚡ Opportunities'!H:H,'⚡ Opportunities'!C:C,">="&AA9,'⚡ Opportunities'!C:C,"<"&EDATE(AA9,1),'⚡ Opportunities'!F:F,TRUE,'⚡ Opportunities'!G:G,TRUE) -> 79860
B10: Average Count of New Leads (Previous Three Months) | D10: Average Deal Size (Previous Three Months) | F10: Total Forecasted Leads (in 12 Months) | H10: Total Forecasted Meetings Booked (in 12 Months) | J10: Total Forecasted Closed/Won (in 12 Months) | L10: Total Forecasted Revenue (in 12 Months) | N10: Total Forecasted Revenue (in 24 Months) | R10: 46235 | S10: 90.633558 | T10: 120.54904 | U10: 112.63849 | V10: 62.04986 | W10: 99836.217 | X10: 798051.97 | Y10: $100k | AA10: =EDATE(AA11,-1) -> 45505 | AB10: =COUNTIFS('⚡ Leads'!D:D,">="&AA10,'⚡ Leads'!D:D,"<"&EDATE(AA10,1)) -> 80 | AC10: =COUNTIFS('⚡ Events'!C:C,">="&AA10,'⚡ Events'!C:C,"<"&EDATE(AA10,1)) -> 107 | AD10: =COUNTIFS('⚡ Opportunities'!C:C,">="&AA10,'⚡ Opportunities'!C:C,"<"&EDATE(AA10,1)) -> 99 | AE10: =COUNTIFS('⚡ Opportunities'!C:C,">="&AA10,'⚡ Opportunities'!C:C,"<"&EDATE(AA10,1),'⚡ Opportunities'!F:F,TRUE,'⚡ Opportunities'!G:G,TRUE) -> 60 | AF10: =SUMIFS('⚡ Opportunities'!H:H,'⚡ Opportunities'!C:C,">="&AA10,'⚡ Opportunities'!C:C,"<"&EDATE(AA10,1),'⚡ Opportunities'!F:F,TRUE,'⚡ Opportunities'!G:G,TRUE) -> 128540 | AH10: =EDATE(AH11,-1) -> 45505 | AI10: =COUNTIFS('⚡ Leads'!D:D,">="&AA10,'⚡ Leads'!D:D,"<"&EDATE(AA10,1)) -> 80 | AJ10: =COUNTIFS('⚡ Events'!C:C,">="&AA10,'⚡ Events'!C:C,"<"&EDATE(AA10,1)) -> 107 | AK10: =COUNTIFS('⚡ Opportunities'!C:C,">="&AA10,'⚡ Opportunities'!C:C,"<"&EDATE(AA10,1)) -> 99 | AL10: =COUNTIFS('⚡ Opportunities'!C:C,">="&AA10,'⚡ Opportunities'!C:C,"<"&EDATE(AA10,1),'⚡ Opportunities'!F:F,TRUE,'⚡ Opportunities'!G:G,TRUE) -> 60 | AM10: =SUMIFS('⚡ Opportunities'!H:H,'⚡ Opportunities'!C:C,">="&AA10,'⚡ Opportunities'!C:C,"<"&EDATE(AA10,1),'⚡ Opportunities'!F:F,TRUE,'⚡ Opportunities'!G:G,TRUE) -> 128540 | AO10: =EDATE(AO11,-1) -> 45444 | AP10: =COUNTIFS('⚡ Leads'!D:D,">="&AA10,'⚡ Leads'!D:D,"<"&EDATE(AA10,1)) -> 80 | AQ10: =COUNTIFS('⚡ Events'!C:C,">="&AA10,'⚡ Events'!C:C,"<"&EDATE(AA10,1)) -> 107 | AR10: =COUNTIFS('⚡ Opportunities'!C:C,">="&AA10,'⚡ Opportunities'!C:C,"<"&EDATE(AA10,1)) -> 99 | AS10: =COUNTIFS('⚡ Opportunities'!C:C,">="&AA10,'⚡ Opportunities'!C:C,"<"&EDATE(AA10,1),'⚡ Opportunities'!F:F,TRUE,'⚡ Opportunities'!G:G,TRUE) -> 60 | AT10: =SUMIFS('⚡ Opportunities'!H:H,'⚡ Opportunities'!C:C,">="&AA10,'⚡ Opportunities'!C:C,"<"&EDATE(AA10,1),'⚡ Opportunities'!F:F,TRUE,'⚡ Opportunities'!G:G,TRUE) -> 128540
B11: 109 | D11: 1691.8508 | F11: =SUM(D16:O16) -> 1081.3696 | H11: =SUM(D17:O17) -> 1438.7012 | J11: =SUM(D19:O19) -> 741.06738 | L11: =O22 -> 1197230.8 | N11: =X26 -> 2392056.2 | R11: 46266 | S11: 90.728186 | T11: 120.6562 | U11: 112.76886 | V11: 62.21574 | W11: 100041.74 | X11: 898093.71 | Y11: $100k | AA11: =EDATE(AA12,-1) -> 45536 | AB11: =COUNTIFS('⚡ Leads'!D:D,">="&AA11,'⚡ Leads'!D:D,"<"&EDATE(AA11,1)) -> 78 | AC11: =COUNTIFS('⚡ Events'!C:C,">="&AA11,'⚡ Events'!C:C,"<"&EDATE(AA11,1)) -> 106 | AD11: =COUNTIFS('⚡ Opportunities'!C:C,">="&AA11,'⚡ Opportunities'!C:C,"<"&EDATE(AA11,1)) -> 95 | AE11: =COUNTIFS('⚡ Opportunities'!C:C,">="&AA11,'⚡ Opportunities'!C:C,"<"&EDATE(AA11,1),'⚡ Opportunities'!F:F,TRUE,'⚡ Opportunities'!G:G,TRUE) -> 59 | AF11: =SUMIFS('⚡ Opportunities'!H:H,'⚡ Opportunities'!C:C,">="&AA11,'⚡ Opportunities'!C:C,"<"&EDATE(AA11,1),'⚡ Opportunities'!F:F,TRUE,'⚡ Opportunities'!G:G,TRUE) -> 108840 | AH11: =EDATE(AH12,-1) -> 45536 | AI11: =COUNTIFS('⚡ Leads'!D:D,">="&AA11,'⚡ Leads'!D:D,"<"&EDATE(AA11,1)) -> 78 | AJ11: =COUNTIFS('⚡ Events'!C:C,">="&AA11,'⚡ Events'!C:C,"<"&EDATE(AA11,1)) -> 106 | AK11: =COUNTIFS('⚡ Opportunities'!C:C,">="&AA11,'⚡ Opportunities'!C:C,"<"&EDATE(AA11,1)) -> 95 | AL11: =COUNTIFS('⚡ Opportunities'!C:C,">="&AA11,'⚡ Opportunities'!C:C,"<"&EDATE(AA11,1),'⚡ Opportunities'!F:F,TRUE,'⚡ Opportunities'!G:G,TRUE) -> 59 | AM11: =SUMIFS('⚡ Opportunities'!H:H,'⚡ Opportunities'!C:C,">="&AA11,'⚡ Opportunities'!C:C,"<"&EDATE(AA11,1),'⚡ Opportunities'!F:F,TRUE,'⚡ Opportunities'!G:G,TRUE) -> 108840 | AO11: =EDATE(AO12,-1) -> 45474 | AP11: =COUNTIFS('⚡ Leads'!D:D,">="&AA11,'⚡ Leads'!D:D,"<"&EDATE(AA11,1)) -> 78 | AQ11: =COUNTIFS('⚡ Events'!C:C,">="&AA11,'⚡ Events'!C:C,"<"&EDATE(AA11,1)) -> 106 | AR11: =COUNTIFS('⚡ Opportunities'!C:C,">="&AA11,'⚡ Opportunities'!C:C,"<"&EDATE(AA11,1)) -> 95 | AS11: =COUNTIFS('⚡ Opportunities'!C:C,">="&AA11,'⚡ Opportunities'!C:C,"<"&EDATE(AA11,1),'⚡ Opportunities'!F:F,TRUE,'⚡ Opportunities'!G:G,TRUE) -> 59 | AT11: =SUMIFS('⚡ Opportunities'!H:H,'⚡ Opportunities'!C:C,">="&AA11,'⚡ Opportunities'!C:C,"<"&EDATE(AA11,1),'⚡ Opportunities'!F:F,TRUE,'⚡ Opportunities'!G:G,TRUE) -> 108840
R12: 46296 | S12: 90.753632 | T12: 120.65552 | U12: 112.77632 | V12: 62.339217 | W12: 99855.707 | X12: 997949.41 | Y12: $100k | AA12: =EDATE(AA13,-1) -> 45566 | AB12: =COUNTIFS('⚡ Leads'!D:D,">="&AA12,'⚡ Leads'!D:D,"<"&EDATE(AA12,1)) -> 82 | AC12: =COUNTIFS('⚡ Events'!C:C,">="&AA12,'⚡ Events'!C:C,"<"&EDATE(AA12,1)) -> 111 | AD12: =COUNTIFS('⚡ Opportunities'!C:C,">="&AA12,'⚡ Opportunities'!C:C,"<"&EDATE(AA12,1)) -> 101 | AE12: =COUNTIFS('⚡ Opportunities'!C:C,">="&AA12,'⚡ Opportunities'!C:C,"<"&EDATE(AA12,1),'⚡ Opportunities'!F:F,TRUE,'⚡ Opportunities'!G:G,TRUE) -> 51 | AF12: =SUMIFS('⚡ Opportunities'!H:H,'⚡ Opportunities'!C:C,">="&AA12,'⚡ Opportunities'!C:C,"<"&EDATE(AA12,1),'⚡ Opportunities'!F:F,TRUE,'⚡ Opportunities'!G:G,TRUE) -> 95780 | AH12: =EDATE(AH13,-1) -> 45566 | AI12: =COUNTIFS('⚡ Leads'!D:D,">="&AA12,'⚡ Leads'!D:D,"<"&EDATE(AA12,1)) -> 82 | AJ12: =COUNTIFS('⚡ Events'!C:C,">="&AA12,'⚡ Events'!C:C,"<"&EDATE(AA12,1)) -> 111 | AK12: =COUNTIFS('⚡ Opportunities'!C:C,">="&AA12,'⚡ Opportunities'!C:C,"<"&EDATE(AA12,1)) -> 101 | AL12: =COUNTIFS('⚡ Opportunities'!C:C,">="&AA12,'⚡ Opportunities'!C:C,"<"&EDATE(AA12,1),'⚡ Opportunities'!F:F,TRUE,'⚡ Opportunities'!G:G,TRUE) -> 51 | AM12: =SUMIFS('⚡ Opportunities'!H:H,'⚡ Opportunities'!C:C,">="&AA12,'⚡ Opportunities'!C:C,"<"&EDATE(AA12,1),'⚡ Opportunities'!F:F,TRUE,'⚡ Opportunities'!G:G,TRUE) -> 95780 | AO12: =EDATE(AO13,-1) -> 45505 | AP12: =COUNTIFS('⚡ Leads'!D:D,">="&AA12,'⚡ Leads'!D:D,"<"&EDATE(AA12,1)) -> 82 | AQ12: =COUNTIFS('⚡ Events'!C:C,">="&AA12,'⚡ Events'!C:C,"<"&EDATE(AA12,1)) -> 111 | AR12: =COUNTIFS('⚡ Opportunities'!C:C,">="&AA12,'⚡ Opportunities'!C:C,"<"&EDATE(AA12,1)) -> 101 | AS12: =COUNTIFS('⚡ Opportunities'!C:C,">="&AA12,'⚡ Opportunities'!C:C,"<"&EDATE(AA12,1),'⚡ Opportunities'!F:F,TRUE,'⚡ Opportunities'!G:G,TRUE) -> 51 | AT12: =SUMIFS('⚡ Opportunities'!H:H,'⚡ Opportunities'!C:C,">="&AA12,'⚡ Opportunities'!C:C,"<"&EDATE(AA12,1),'⚡ Opportunities'!F:F,TRUE,'⚡ Opportunities'!G:G,TRUE) -> 95780
R13: 46327 | S13: 90.676973 | T13: 120.54505 | U13: 112.66201 | V13: 62.336107 | W13: 99698.242 | X13: 1097647.7 | Y13: $100k | AA13: =EDATE(AA14,-1) -> 45597 | AB13: =COUNTIFS('⚡ Leads'!D:D,">="&AA13,'⚡ Leads'!D:D,"<"&EDATE(AA13,1)) -> 86 | AC13: =COUNTIFS('⚡ Events'!C:C,">="&AA13,'⚡ Events'!C:C,"<"&EDATE(AA13,1)) -> 114 | AD13: =COUNTIFS('⚡ Opportunities'!C:C,">="&AA13,'⚡ Opportunities'!C:C,"<"&EDATE(AA13,1)) -> 105 | AE13: =COUNTIFS('⚡ Opportunities'!C:C,">="&AA13,'⚡ Opportunities'!C:C,"<"&EDATE(AA13,1),'⚡ Opportunities'!F:F,TRUE,'⚡ Opportunities'!G:G,TRUE) -> 60 | AF13: =SUMIFS('⚡ Opportunities'!H:H,'⚡ Opportunities'!C:C,">="&AA13,'⚡ Opportunities'!C:C,"<"&EDATE(AA13,1),'⚡ Opportunities'!F:F,TRUE,'⚡ Opportunities'!G:G,TRUE) -> 155620 | AH13: =EDATE(AH14,-1) -> 45597 | AI13: =COUNTIFS('⚡ Leads'!D:D,">="&AA13,'⚡ Leads'!D:D,"<"&EDATE(AA13,1)) -> 86 | AJ13: =COUNTIFS('⚡ Events'!C:C,">="&AA13,'⚡ Events'!C:C,"<"&EDATE(AA13,1)) -> 114 | AK13: =COUNTIFS('⚡ Opportunities'!C:C,">="&AA13,'⚡ Opportunities'!C:C,"<"&EDATE(AA13,1)) -> 105 | AL13: =COUNTIFS('⚡ Opportunities'!C:C,">="&AA13,'⚡ Opportunities'!C:C,"<"&EDATE(AA13,1),'⚡ Opportunities'!F:F,TRUE,'⚡ Opportunities'!G:G,TRUE) -> 60 | AM13: =SUMIFS('⚡ Opportunities'!H:H,'⚡ Opportunities'!C:C,">="&AA13,'⚡ Opportunities'!C:C,"<"&EDATE(AA13,1),'⚡ Opportunities'!F:F,TRUE,'⚡ Opportunities'!G:G,TRUE) -> 155620 | AO13: =EDATE(AO14,-1) -> 45536 | AP13: =COUNTIFS('⚡ Leads'!D:D,">="&AA13,'⚡ Leads'!D:D,"<"&EDATE(AA13,1)) -> 86 | AQ13: =COUNTIFS('⚡ Events'!C:C,">="&AA13,'⚡ Events'!C:C,"<"&EDATE(AA13,1)) -> 114 | AR13: =COUNTIFS('⚡ Opportunities'!C:C,">="&AA13,'⚡ Opportunities'!C:C,"<"&EDATE(AA13,1)) -> 105 | AS13: =COUNTIFS('⚡ Opportunities'!C:C,">="&AA13,'⚡ Opportunities'!C:C,"<"&EDATE(AA13,1),'⚡ Opportunities'!F:F,TRUE,'⚡ Opportunities'!G:G,TRUE) -> 60 | AT13: =SUMIFS('⚡ Opportunities'!H:H,'⚡ Opportunities'!C:C,">="&AA13,'⚡ Opportunities'!C:C,"<"&EDATE(AA13,1),'⚡ Opportunities'!F:F,TRUE,'⚡ Opportunities'!G:G,TRUE) -> 155620
D14: =EOMONTH(TODAY(),-1)+1 -> 46023 | E14: 45778 | F14: 45809 | G14: 45839 | H14: 45870 | I14: 45901 | J14: 45931 | K14: 45962 | L14: 45992 | M14: 46023 | N14: 46054 | O14: 46082 | R14: 46357 | S14: 90.561464 | T14: 120.39665 | U14: 112.50361 | V14: 62.272106 | W14: 99583.123 | X14: 1197230.8 | Y14: $100k | AA14: =EDATE(AA15,-1) -> 45627 | AB14: =COUNTIFS('⚡ Leads'!D:D,">="&AA14,'⚡ Leads'!D:D,"<"&EDATE(AA14,1)) -> 87 | AC14: =COUNTIFS('⚡ Events'!C:C,">="&AA14,'⚡ Events'!C:C,"<"&EDATE(AA14,1)) -> 118 | AD14: =COUNTIFS('⚡ Opportunities'!C:C,">="&AA14,'⚡ Opportunities'!C:C,"<"&EDATE(AA14,1)) -> 107 | AE14: =COUNTIFS('⚡ Opportunities'!C:C,">="&AA14,'⚡ Opportunities'!C:C,"<"&EDATE(AA14,1),'⚡ Opportunities'!F:F,TRUE,'⚡ Opportunities'!G:G,TRUE) -> 48 | AF14: =SUMIFS('⚡ Opportunities'!H:H,'⚡ Opportunities'!C:C,">="&AA14,'⚡ Opportunities'!C:C,"<"&EDATE(AA14,1),'⚡ Opportunities'!F:F,TRUE,'⚡ Opportunities'!G:G,TRUE) -> 63150 | AH14: =EDATE(AH15,-1) -> 45627 | AI14: =COUNTIFS('⚡ Leads'!D:D,">="&AA14,'⚡ Leads'!D:D,"<"&EDATE(AA14,1)) -> 87 | AJ14: =COUNTIFS('⚡ Events'!C:C,">="&AA14,'⚡ Events'!C:C,"<"&EDATE(AA14,1)) -> 118 | AK14: =COUNTIFS('⚡ Opportunities'!C:C,">="&AA14,'⚡ Opportunities'!C:C,"<"&EDATE(AA14,1)) -> 107 | AL14: =COUNTIFS('⚡ Opportunities'!C:C,">="&AA14,'⚡ Opportunities'!C:C,"<"&EDATE(AA14,1),'⚡ Opportunities'!F:F,TRUE,'⚡ Opportunities'!G:G,TRUE) -> 48 | AM14: =SUMIFS('⚡ Opportunities'!H:H,'⚡ Opportunities'!C:C,">="&AA14,'⚡ Opportunities'!C:C,"<"&EDATE(AA14,1),'⚡ Opportunities'!F:F,TRUE,'⚡ Opportunities'!G:G,TRUE) -> 63150 | AO14: =EDATE(AO15,-1) -> 45566 | AP14: =COUNTIFS('⚡ Leads'!D:D,">="&AA14,'⚡ Leads'!D:D,"<"&EDATE(AA14,1)) -> 87 | AQ14: =COUNTIFS('⚡ Events'!C:C,">="&AA14,'⚡ Events'!C:C,"<"&EDATE(AA14,1)) -> 118 | AR14: =COUNTIFS('⚡ Opportunities'!C:C,">="&AA14,'⚡ Opportunities'!C:C,"<"&EDATE(AA14,1)) -> 107 | AS14: =COUNTIFS('⚡ Opportunities'!C:C,">="&AA14,'⚡ Opportunities'!C:C,"<"&EDATE(AA14,1),'⚡ Opportunities'!F:F,TRUE,'⚡ Opportunities'!G:G,TRUE) -> 48 | AT14: =SUMIFS('⚡ Opportunities'!H:H,'⚡ Opportunities'!C:C,">="&AA14,'⚡ Opportunities'!C:C,"<"&EDATE(AA14,1),'⚡ Opportunities'!F:F,TRUE,'⚡ Opportunities'!G:G,TRUE) -> 63150
R15: 46388 | S15: 90.443624 | T15: 120.25122 | U15: 112.34567 | V15: 62.187434 | W15: 99513.78 | X15: 1296744.6 | Y15: $100k | AA15: =EDATE(AA16,-1) -> 45658 | AB15: =COUNTIFS('⚡ Leads'!D:D,">="&AA15,'⚡ Leads'!D:D,"<"&EDATE(AA15,1)) -> 90 | AC15: =COUNTIFS('⚡ Events'!C:C,">="&AA15,'⚡ Events'!C:C,"<"&EDATE(AA15,1)) -> 119 | AD15: =COUNTIFS('⚡ Opportunities'!C:C,">="&AA15,'⚡ Opportunities'!C:C,"<"&EDATE(AA15,1)) -> 111 | AE15: =COUNTIFS('⚡ Opportunities'!C:C,">="&AA15,'⚡ Opportunities'!C:C,"<"&EDATE(AA15,1),'⚡ Opportunities'!F:F,TRUE,'⚡ Opportunities'!G:G,TRUE) -> 56 | AF15: =SUMIFS('⚡ Opportunities'!H:H,'⚡ Opportunities'!C:C,">="&AA15,'⚡ Opportunities'!C:C,"<"&EDATE(AA15,1),'⚡ Opportunities'!F:F,TRUE,'⚡ Opportunities'!G:G,TRUE) -> 74090 | AH15: =EDATE(AH16,-1) -> 45658 | AI15: =COUNTIFS('⚡ Leads'!D:D,">="&AA15,'⚡ Leads'!D:D,"<"&EDATE(AA15,1)) -> 90 | AJ15: =COUNTIFS('⚡ Events'!C:C,">="&AA15,'⚡ Events'!C:C,"<"&EDATE(AA15,1)) -> 119 | AK15: =COUNTIFS('⚡ Opportunities'!C:C,">="&AA15,'⚡ Opportunities'!C:C,"<"&EDATE(AA15,1)) -> 111 | AL15: =COUNTIFS('⚡ Opportunities'!C:C,">="&AA15,'⚡ Opportunities'!C:C,"<"&EDATE(AA15,1),'⚡ Opportunities'!F:F,TRUE,'⚡ Opportunities'!G:G,TRUE) -> 56 | AM15: =SUMIFS('⚡ Opportunities'!H:H,'⚡ Opportunities'!C:C,">="&AA15,'⚡ Opportunities'!C:C,"<"&EDATE(AA15,1),'⚡ Opportunities'!F:F,TRUE,'⚡ Opportunities'!G:G,TRUE) -> 74090 | AO15: =EDATE(AO16,-1) -> 45597 | AP15: =COUNTIFS('⚡ Leads'!D:D,">="&AA15,'⚡ Leads'!D:D,"<"&EDATE(AA15,1)) -> 90 | AQ15: =COUNTIFS('⚡ Events'!C:C,">="&AA15,'⚡ Events'!C:C,"<"&EDATE(AA15,1)) -> 119 | AR15: =COUNTIFS('⚡ Opportunities'!C:C,">="&AA15,'⚡ Opportunities'!C:C,"<"&EDATE(AA15,1)) -> 111 | AS15: =COUNTIFS('⚡ Opportunities'!C:C,">="&AA15,'⚡ Opportunities'!C:C,"<"&EDATE(AA15,1),'⚡ Opportunities'!F:F,TRUE,'⚡ Opportunities'!G:G,TRUE) -> 56 | AT15: =SUMIFS('⚡ Opportunities'!H:H,'⚡ Opportunities'!C:C,">="&AA15,'⚡ Opportunities'!C:C,"<"&EDATE(AA15,1),'⚡ Opportunities'!F:F,TRUE,'⚡ Opportunities'!G:G,TRUE) -> 74090
B16: Acquired Leads | D16: {=TRANSPOSE(S3:S14)} -> 88.979183 | E16: 89.149743 | F16: 89.417364 | G16: 89.718724 | H16: 90.003562 | I16: 90.266768 | J16: 90.480472 | K16: 90.633558 | L16: 90.728186 | M16: 90.753632 | N16: 90.676973 | O16: 90.561464 | R16: 46419 | S16: 90.342503 | T16: 120.12945 | U16: 112.21146 | V16: 62.104786 | W16: 99487.152 | X16: 1396231.7 | Y16: $99k | AA16: =EDATE(AA17,-1) -> 45689 | AB16: =COUNTIFS('⚡ Leads'!D:D,">="&AA16,'⚡ Leads'!D:D,"<"&EDATE(AA16,1)) -> 92 | AC16: =COUNTIFS('⚡ Events'!C:C,">="&AA16,'⚡ Events'!C:C,"<"&EDATE(AA16,1)) -> 121 | AD16: =COUNTIFS('⚡ Opportunities'!C:C,">="&AA16,'⚡ Opportunities'!C:C,"<"&EDATE(AA16,1)) -> 114 | AE16: =COUNTIFS('⚡ Opportunities'!C:C,">="&AA16,'⚡ Opportunities'!C:C,"<"&EDATE(AA16,1),'⚡ Opportunities'!F:F,TRUE,'⚡ Opportunities'!G:G,TRUE) -> 67 | AF16: =SUMIFS('⚡ Opportunities'!H:H,'⚡ Opportunities'!C:C,">="&AA16,'⚡ Opportunities'!C:C,"<"&EDATE(AA16,1),'⚡ Opportunities'!F:F,TRUE,'⚡ Opportunities'!G:G,TRUE) -> 100160 | AH16: =EDATE(AH17,-1) -> 45689 | AI16: =COUNTIFS('⚡ Leads'!D:D,">="&AA16,'⚡ Leads'!D:D,"<"&EDATE(AA16,1)) -> 92 | AJ16: =COUNTIFS('⚡ Events'!C:C,">="&AA16,'⚡ Events'!C:C,"<"&EDATE(AA16,1)) -> 121 | AK16: =COUNTIFS('⚡ Opportunities'!C:C,">="&AA16,'⚡ Opportunities'!C:C,"<"&EDATE(AA16,1)) -> 114 | AL16: =COUNTIFS('⚡ Opportunities'!C:C,">="&AA16,'⚡ Opportunities'!C:C,"<"&EDATE(AA16,1),'⚡ Opportunities'!F:F,TRUE,'⚡ Opportunities'!G:G,TRUE) -> 67 | AM16: =SUMIFS('⚡ Opportunities'!H:H,'⚡ Opportunities'!C:C,">="&AA16,'⚡ Opportunities'!C:C,"<"&EDATE(AA16,1),'⚡ Opportunities'!F:F,TRUE,'⚡ Opportunities'!G:G,TRUE) -> 100160 | AO16: =EDATE(AO17,-1) -> 45627 | AP16: =COUNTIFS('⚡ Leads'!D:D,">="&AA16,'⚡ Leads'!D:D,"<"&EDATE(AA16,1)) -> 92 | AQ16: =COUNTIFS('⚡ Events'!C:C,">="&AA16,'⚡ Events'!C:C,"<"&EDATE(AA16,1)) -> 121 | AR16: =COUNTIFS('⚡ Opportunities'!C:C,">="&AA16,'⚡ Opportunities'!C:C,"<"&EDATE(AA16,1)) -> 114 | AS16: =COUNTIFS('⚡ Opportunities'!C:C,">="&AA16,'⚡ Opportunities'!C:C,"<"&EDATE(AA16,1),'⚡ Opportunities'!F:F,TRUE,'⚡ Opportunities'!G:G,TRUE) -> 67 | AT16: =SUMIFS('⚡ Opportunities'!H:H,'⚡ Opportunities'!C:C,">="&AA16,'⚡ Opportunities'!C:C,"<"&EDATE(AA16,1),'⚡ Opportunities'!F:F,TRUE,'⚡ Opportunities'!G:G,TRUE) -> 100160
B17: Meetings Booked | D17: {=TRANSPOSE(T3:V14)} -> 118.47633 | E17: 118.71602 | F17: 119.05736 | G17: 119.42523 | H17: 119.78335 | I17: 120.09083 | J17: 120.34964 | K17: 120.54904 | L17: 120.6562 | M17: 120.65552 | N17: 120.54505 | O17: 120.39665 | R17: 46447 | S17: 90.266219 | T17: 120.0397 | U17: 112.1108 | V17: 62.03574 | W17: 99493.347 | X17: 1495725.1 | Y17: $99k | AA17: =EDATE(AA18,-1) -> 45717 | AB17: =COUNTIFS('⚡ Leads'!D:D,">="&AA17,'⚡ Leads'!D:D,"<"&EDATE(AA17,1)) -> 93 | AC17: =COUNTIFS('⚡ Events'!C:C,">="&AA17,'⚡ Events'!C:C,"<"&EDATE(AA17,1)) -> 125 | AD17: =COUNTIFS('⚡ Opportunities'!C:C,">="&AA17,'⚡ Opportunities'!C:C,"<"&EDATE(AA17,1)) -> 117 | AE17: =COUNTIFS('⚡ Opportunities'!C:C,">="&AA17,'⚡ Opportunities'!C:C,"<"&EDATE(AA17,1),'⚡ Opportunities'!F:F,TRUE,'⚡ Opportunities'!G:G,TRUE) -> 58 | AF17: =SUMIFS('⚡ Opportunities'!H:H,'⚡ Opportunities'!C:C,">="&AA17,'⚡ Opportunities'!C:C,"<"&EDATE(AA17,1),'⚡ Opportunities'!F:F,TRUE,'⚡ Opportunities'!G:G,TRUE) -> 95800 | AH17: =EDATE(AH18,-1) -> 45717 | AI17: =COUNTIFS('⚡ Leads'!D:D,">="&AA17,'⚡ Leads'!D:D,"<"&EDATE(AA17,1)) -> 93 | AJ17: =COUNTIFS('⚡ Events'!C:C,">="&AA17,'⚡ Events'!C:C,"<"&EDATE(AA17,1)) -> 125 | AK17: =COUNTIFS('⚡ Opportunities'!C:C,">="&AA17,'⚡ Opportunities'!C:C,"<"&EDATE(AA17,1)) -> 117 | AL17: =COUNTIFS('⚡ Opportunities'!C:C,">="&AA17,'⚡ Opportunities'!C:C,"<"&EDATE(AA17,1),'⚡ Opportunities'!F:F,TRUE,'⚡ Opportunities'!G:G,TRUE) -> 58 | AM17: =SUMIFS('⚡ Opportunities'!H:H,'⚡ Opportunities'!C:C,">="&AA17,'⚡ Opportunities'!C:C,"<"&EDATE(AA17,1),'⚡ Opportunities'!F:F,TRUE,'⚡ Opportunities'!G:G,TRUE) -> 95800 | AO17: =EDATE(AO18,-1) -> 45658 | AP17: =COUNTIFS('⚡ Leads'!D:D,">="&AA17,'⚡ Leads'!D:D,"<"&EDATE(AA17,1)) -> 93 | AQ17: =COUNTIFS('⚡ Events'!C:C,">="&AA17,'⚡ Events'!C:C,"<"&EDATE(AA17,1)) -> 125 | AR17: =COUNTIFS('⚡ Opportunities'!C:C,">="&AA17,'⚡ Opportunities'!C:C,"<"&EDATE(AA17,1)) -> 117 | AS17: =COUNTIFS('⚡ Opportunities'!C:C,">="&AA17,'⚡ Opportunities'!C:C,"<"&EDATE(AA17,1),'⚡ Opportunities'!F:F,TRUE,'⚡ Opportunities'!G:G,TRUE) -> 58 | AT17: =SUMIFS('⚡ Opportunities'!H:H,'⚡ Opportunities'!C:C,">="&AA17,'⚡ Opportunities'!C:C,"<"&EDATE(AA17,1),'⚡ Opportunities'!F:F,TRUE,'⚡ Opportunities'!G:G,TRUE) -> 95800
B18: New Opportunities | D18: 110.40166 | E18: 110.60535 | F18: 110.9519 | G18: 111.34622 | H18: 111.73633 | I18: 112.10414 | J18: 112.41139 | K18: 112.63849 | L18: 112.76886 | M18: 112.77632 | N18: 112.66201 | O18: 112.50361 | R18: 46478 | S18: 90.216405 | T18: 119.98306 | U18: 112.04517 | V18: 61.983895 | W18: 99519.182 | X18: 1595244.2 | Y18: $100k | AA18: =EDATE(AA19,-1) -> 45748 | AB18: =COUNTIFS('⚡ Leads'!D:D,">="&AA18,'⚡ Leads'!D:D,"<"&EDATE(AA18,1)) -> 95 | AC18: =COUNTIFS('⚡ Events'!C:C,">="&AA18,'⚡ Events'!C:C,"<"&EDATE(AA18,1)) -> 128 | AD18: =COUNTIFS('⚡ Opportunities'!C:C,">="&AA18,'⚡ Opportunities'!C:C,"<"&EDATE(AA18,1)) -> 121 | AE18: =COUNTIFS('⚡ Opportunities'!C:C,">="&AA18,'⚡ Opportunities'!C:C,"<"&EDATE(AA18,1),'⚡ Opportunities'!F:F,TRUE,'⚡ Opportunities'!G:G,TRUE) -> 63 | AF18: =SUMIFS('⚡ Opportunities'!H:H,'⚡ Opportunities'!C:C,">="&AA18,'⚡ Opportunities'!C:C,"<"&EDATE(AA18,1),'⚡ Opportunities'!F:F,TRUE,'⚡ Opportunities'!G:G,TRUE) -> 129830 | AH18: =EDATE(AH19,-1) -> 45748 | AI18: =COUNTIFS('⚡ Leads'!D:D,">="&AA18,'⚡ Leads'!D:D,"<"&EDATE(AA18,1)) -> 95 | AJ18: =COUNTIFS('⚡ Events'!C:C,">="&AA18,'⚡ Events'!C:C,"<"&EDATE(AA18,1)) -> 128 | AK18: =COUNTIFS('⚡ Opportunities'!C:C,">="&AA18,'⚡ Opportunities'!C:C,"<"&EDATE(AA18,1)) -> 121 | AL18: =COUNTIFS('⚡ Opportunities'!C:C,">="&AA18,'⚡ Opportunities'!C:C,"<"&EDATE(AA18,1),'⚡ Opportunities'!F:F,TRUE,'⚡ Opportunities'!G:G,TRUE) -> 63 | AM18: =SUMIFS('⚡ Opportunities'!H:H,'⚡ Opportunities'!C:C,">="&AA18,'⚡ Opportunities'!C:C,"<"&EDATE(AA18,1),'⚡ Opportunities'!F:F,TRUE,'⚡ Opportunities'!G:G,TRUE) -> 129830 | AO18: =EDATE(AO19,-1) -> 45689 | AP18: =COUNTIFS('⚡ Leads'!D:D,">="&AA18,'⚡ Leads'!D:D,"<"&EDATE(AA18,1)) -> 95 | AQ18: =COUNTIFS('⚡ Events'!C:C,">="&AA18,'⚡ Events'!C:C,"<"&EDATE(AA18,1)) -> 128 | AR18: =COUNTIFS('⚡ Opportunities'!C:C,">="&AA18,'⚡ Opportunities'!C:C,"<"&EDATE(AA18,1)) -> 121 | AS18: =COUNTIFS('⚡ Opportunities'!C:C,">="&AA18,'⚡ Opportunities'!C:C,"<"&EDATE(AA18,1),'⚡ Opportunities'!F:F,TRUE,'⚡ Opportunities'!G:G,TRUE) -> 63 | AT18: =SUMIFS('⚡ Opportunities'!H:H,'⚡ Opportunities'!C:C,">="&AA18,'⚡ Opportunities'!C:C,"<"&EDATE(AA18,1),'⚡ Opportunities'!F:F,TRUE,'⚡ Opportunities'!G:G,TRUE) -> 129830
B19: Closed/Won | D19: 61.237095 | E19: 61.192974 | F19: 61.183476 | G19: 61.295684 | H19: 61.400693 | I19: 61.642356 | J19: 61.902067 | K19: 62.04986 | L19: 62.21574 | M19: 62.339217 | N19: 62.336107 | O19: 62.272106 | R19: 46508 | S19: 90.1912 | T19: 119.95645 | U19: 112.01183 | V19: 61.948171 | W19: 99549.678 | X19: 1694793.9 | Y19: $100k | AA19: =EDATE(AA20,-1) -> 45778 | AB19: =COUNTIFS('⚡ Leads'!D:D,">="&AA19,'⚡ Leads'!D:D,"<"&EDATE(AA19,1)) -> 99 | AC19: =COUNTIFS('⚡ Events'!C:C,">="&AA19,'⚡ Events'!C:C,"<"&EDATE(AA19,1)) -> 130 | AD19: =COUNTIFS('⚡ Opportunities'!C:C,">="&AA19,'⚡ Opportunities'!C:C,"<"&EDATE(AA19,1)) -> 123 | AE19: =COUNTIFS('⚡ Opportunities'!C:C,">="&AA19,'⚡ Opportunities'!C:C,"<"&EDATE(AA19,1),'⚡ Opportunities'!F:F,TRUE,'⚡ Opportunities'!G:G,TRUE) -> 71 | AF19: =SUMIFS('⚡ Opportunities'!H:H,'⚡ Opportunities'!C:C,">="&AA19,'⚡ Opportunities'!C:C,"<"&EDATE(AA19,1),'⚡ Opportunities'!F:F,TRUE,'⚡ Opportunities'!G:G,TRUE) -> 100590 | AH19: =EDATE(AH20,-1) -> 45778 | AI19: =COUNTIFS('⚡ Leads'!D:D,">="&AA19,'⚡ Leads'!D:D,"<"&EDATE(AA19,1)) -> 99 | AJ19: =COUNTIFS('⚡ Events'!C:C,">="&AA19,'⚡ Events'!C:C,"<"&EDATE(AA19,1)) -> 130 | AK19: =COUNTIFS('⚡ Opportunities'!C:C,">="&AA19,'⚡ Opportunities'!C:C,"<"&EDATE(AA19,1)) -> 123 | AL19: =COUNTIFS('⚡ Opportunities'!C:C,">="&AA19,'⚡ Opportunities'!C:C,"<"&EDATE(AA19,1),'⚡ Opportunities'!F:F,TRUE,'⚡ Opportunities'!G:G,TRUE) -> 71 | AM19: =SUMIFS('⚡ Opportunities'!H:H,'⚡ Opportunities'!C:C,">="&AA19,'⚡ Opportunities'!C:C,"<"&EDATE(AA19,1),'⚡ Opportunities'!F:F,TRUE,'⚡ Opportunities'!G:G,TRUE) -> 100590 | AO19: =EDATE(AO20,-1) -> 45717 | AP19: =COUNTIFS('⚡ Leads'!D:D,">="&AA19,'⚡ Leads'!D:D,"<"&EDATE(AA19,1)) -> 99 | AQ19: =COUNTIFS('⚡ Events'!C:C,">="&AA19,'⚡ Events'!C:C,"<"&EDATE(AA19,1)) -> 130 | AR19: =COUNTIFS('⚡ Opportunities'!C:C,">="&AA19,'⚡ Opportunities'!C:C,"<"&EDATE(AA19,1)) -> 123 | AS19: =COUNTIFS('⚡ Opportunities'!C:C,">="&AA19,'⚡ Opportunities'!C:C,"<"&EDATE(AA19,1),'⚡ Opportunities'!F:F,TRUE,'⚡ Opportunities'!G:G,TRUE) -> 71 | AT19: =SUMIFS('⚡ Opportunities'!H:H,'⚡ Opportunities'!C:C,">="&AA19,'⚡ Opportunities'!C:C,"<"&EDATE(AA19,1),'⚡ Opportunities'!F:F,TRUE,'⚡ Opportunities'!G:G,TRUE) -> 100590
R20: 46539 | S20: 90.186249 | T20: 119.95411 | U20: 112.00513 | V20: 61.927094 | W20: 99578.494 | X20: 1794372.4 | Y20: $100k | AA20: =EDATE(AA21,-1) -> 45809 | AB20: =COUNTIFS('⚡ Leads'!D:D,">="&AA20,'⚡ Leads'!D:D,"<"&EDATE(AA20,1)) -> 97 | AC20: =COUNTIFS('⚡ Events'!C:C,">="&AA20,'⚡ Events'!C:C,"<"&EDATE(AA20,1)) -> 129 | AD20: =COUNTIFS('⚡ Opportunities'!C:C,">="&AA20,'⚡ Opportunities'!C:C,"<"&EDATE(AA20,1)) -> 122 | AE20: =COUNTIFS('⚡ Opportunities'!C:C,">="&AA20,'⚡ Opportunities'!C:C,"<"&EDATE(AA20,1),'⚡ Opportunities'!F:F,TRUE,'⚡ Opportunities'!G:G,TRUE) -> 65 | AF20: =SUMIFS('⚡ Opportunities'!H:H,'⚡ Opportunities'!C:C,">="&AA20,'⚡ Opportunities'!C:C,"<"&EDATE(AA20,1),'⚡ Opportunities'!F:F,TRUE,'⚡ Opportunities'!G:G,TRUE) -> 98170 | AH20: =EDATE(AH21,-1) -> 45809 | AI20: =COUNTIFS('⚡ Leads'!D:D,">="&AA20,'⚡ Leads'!D:D,"<"&EDATE(AA20,1)) -> 97 | AJ20: =COUNTIFS('⚡ Events'!C:C,">="&AA20,'⚡ Events'!C:C,"<"&EDATE(AA20,1)) -> 129 | AK20: =COUNTIFS('⚡ Opportunities'!C:C,">="&AA20,'⚡ Opportunities'!C:C,"<"&EDATE(AA20,1)) -> 122 | AL20: =COUNTIFS('⚡ Opportunities'!C:C,">="&AA20,'⚡ Opportunities'!C:C,"<"&EDATE(AA20,1),'⚡ Opportunities'!F:F,TRUE,'⚡ Opportunities'!G:G,TRUE) -> 65 | AM20: =SUMIFS('⚡ Opportunities'!H:H,'⚡ Opportunities'!C:C,">="&AA20,'⚡ Opportunities'!C:C,"<"&EDATE(AA20,1),'⚡ Opportunities'!F:F,TRUE,'⚡ Opportunities'!G:G,TRUE) -> 98170 | AO20: =EDATE(AO21,-1) -> 45748 | AP20: =IFERROR(AP19*$G$6+(1-$G$6)*AVERAGE(AP3:AP19),"") -> 95.282353 | AQ20: =IFERROR(AQ19*$G$6+(1-$G$6)*AVERAGE(AQ3:AQ19),"") -> 125.64706 | AR20: =IFERROR(AR19*$G$6+(1-$G$6)*AVERAGE(AR3:AR19),"") -> 118.35294 | AS20: =IFERROR(AS19*$G$6+(1-$G$6)*AVERAGE(AS3:AS19),"") -> 67.564706 | AT20: =IFERROR(AT19*$G$6+(1-$G$6)*AVERAGE(AT3:AT19),"") -> 98775.765
B21: New Forecasted Revenue | D21: {=TRANSPOSE(W3:X14)} -> 99793.517 | E21: 99950.892 | F21: 99972.213 | G21: 100038.59 | H21: 99437.794 | I21: 99384.072 | J21: 99638.671 | K21: 99836.217 | L21: 100041.74 | M21: 99855.707 | N21: 99698.242 | O21: 99583.123 | R21: 46569 | S21: 90.196489 | T21: 119.96963 | U21: 112.01863 | V21: 61.918351 | W21: 99599.018 | X21: 1893971.4 | Y21: $100k | AA21: =EDATE(AA22,-1) -> 45839 | AB21: =COUNTIFS('⚡ Leads'!D:D,">="&AA21,'⚡ Leads'!D:D,"<"&EDATE(AA21,1)) -> 101 | AC21: =COUNTIFS('⚡ Events'!C:C,">="&AA21,'⚡ Events'!C:C,"<"&EDATE(AA21,1)) -> 131 | AD21: =COUNTIFS('⚡ Opportunities'!C:C,">="&AA21,'⚡ Opportunities'!C:C,"<"&EDATE(AA21,1)) -> 126 | AE21: =COUNTIFS('⚡ Opportunities'!C:C,">="&AA21,'⚡ Opportunities'!C:C,"<"&EDATE(AA21,1),'⚡ Opportunities'!F:F,TRUE,'⚡ Opportunities'!G:G,TRUE) -> 65 | AF21: =SUMIFS('⚡ Opportunities'!H:H,'⚡ Opportunities'!C:C,">="&AA21,'⚡ Opportunities'!C:C,"<"&EDATE(AA21,1),'⚡ Opportunities'!F:F,TRUE,'⚡ Opportunities'!G:G,TRUE) -> 107140 | AH21: =EDATE(AH22,-1) -> 45839 | AI21: =COUNTIFS('⚡ Leads'!D:D,">="&AA21,'⚡ Leads'!D:D,"<"&EDATE(AA21,1)) -> 101 | AJ21: =COUNTIFS('⚡ Events'!C:C,">="&AA21,'⚡ Events'!C:C,"<"&EDATE(AA21,1)) -> 131 | AK21: =COUNTIFS('⚡ Opportunities'!C:C,">="&AA21,'⚡ Opportunities'!C:C,"<"&EDATE(AA21,1)) -> 126 | AL21: =COUNTIFS('⚡ Opportunities'!C:C,">="&AA21,'⚡ Opportunities'!C:C,"<"&EDATE(AA21,1),'⚡ Opportunities'!F:F,TRUE,'⚡ Opportunities'!G:G,TRUE) -> 65 | AM21: =SUMIFS('⚡ Opportunities'!H:H,'⚡ Opportunities'!C:C,">="&AA21,'⚡ Opportunities'!C:C,"<"&EDATE(AA21,1),'⚡ Opportunities'!F:F,TRUE,'⚡ Opportunities'!G:G,TRUE) -> 107140 | AO21: =EDATE(AO22,-1) -> 45778 | AP21: =IFERROR(AP20*$G$6+(1-$G$6)*AVERAGE(AP4:AP20),"") -> 92.723322 | AQ21: =IFERROR(AQ20*$G$6+(1-$G$6)*AVERAGE(AQ4:AQ20),"") -> 122.66644 | AR21: =IFERROR(AR20*$G$6+(1-$G$6)*AVERAGE(AR4:AR20),"") -> 115.15709 | AS21: =IFERROR(AS20*$G$6+(1-$G$6)*AVERAGE(AS4:AS20),"") -> 65.117232 | AT21: =IFERROR(AT20*$G$6+(1-$G$6)*AVERAGE(AT4:AT20),"") -> 97649.15
